./run-100-experiments.sh 20 1
terminate called after throwing an instance of 'std::out_of_range'
  what():  vector::_M_range_check
./run-experiments.sh : ligne 99 : 16946 Abandon                 (core dumped) bin/experiments ../data/processed/circuitbreaker-2.txt $1 $2
terminate called after throwing an instance of 'std::out_of_range'
  what():  vector::_M_range_check
./run-experiments.sh : ligne 129 : 17934 Abandon                 (core dumped) bin/experiments ../data/processed/circuitbreaker-32.txt $1 $2
terminate called after throwing an instance of 'std::out_of_range'
  what():  vector::_M_range_check
./run-experiments.sh : ligne 129 : 18706 Abandon                 (core dumped) bin/experiments ../data/processed/circuitbreaker-32.txt $1 $2
